2020-01-08 21:18:55,933:WARNING:discord.gateway: Shard ID None has stopped responding to the gateway. Closing and restarting.
2020-01-08 23:02:45,404:WARNING:discord.gateway: Shard ID None has stopped responding to the gateway. Closing and restarting.
2020-01-09 08:48:40,238:WARNING:discord.gateway: Shard ID None has stopped responding to the gateway. Closing and restarting.
2020-01-09 16:04:01,920:WARNING:discord.gateway: Unknown event PRESENCES_REPLACE.
2020-01-09 21:21:47,675:WARNING:discord.gateway: Shard ID None has stopped responding to the gateway. Closing and restarting.
2020-01-09 21:22:18,953:ERROR:discord.voice_client: Disconnected from voice... Reconnecting in 0.05s.
Traceback (most recent call last):
  File "C:\Users\yuya\AppData\Local\Programs\Python\Python37\lib\site-packages\websockets\protocol.py", line 528, in transfer_data
    msg = yield from self.read_message()
  File "C:\Users\yuya\AppData\Local\Programs\Python\Python37\lib\site-packages\websockets\protocol.py", line 580, in read_message
    frame = yield from self.read_data_frame(max_size=self.max_size)
  File "C:\Users\yuya\AppData\Local\Programs\Python\Python37\lib\site-packages\websockets\protocol.py", line 645, in read_data_frame
    frame = yield from self.read_frame(max_size)
  File "C:\Users\yuya\AppData\Local\Programs\Python\Python37\lib\site-packages\websockets\protocol.py", line 710, in read_frame
    extensions=self.extensions,
  File "C:\Users\yuya\AppData\Local\Programs\Python\Python37\lib\site-packages\websockets\framing.py", line 100, in read
    data = yield from reader(2)
  File "C:\Users\yuya\AppData\Local\Programs\Python\Python37\lib\asyncio\streams.py", line 677, in readexactly
    raise IncompleteReadError(incomplete, n)
asyncio.streams.IncompleteReadError: 0 bytes read on a total of 2 expected bytes

The above exception was the direct cause of the following exception:

Traceback (most recent call last):
  File "C:\Users\yuya\AppData\Local\Programs\Python\Python37\lib\site-packages\discord\gateway.py", line 735, in poll_event
    msg = await asyncio.wait_for(self.recv(), timeout=30.0, loop=self.loop)
  File "C:\Users\yuya\AppData\Local\Programs\Python\Python37\lib\asyncio\tasks.py", line 442, in wait_for
    return fut.result()
  File "C:\Users\yuya\AppData\Local\Programs\Python\Python37\lib\site-packages\websockets\protocol.py", line 350, in recv
    yield from self.ensure_open()
  File "C:\Users\yuya\AppData\Local\Programs\Python\Python37\lib\site-packages\websockets\protocol.py", line 501, in ensure_open
    self.close_code, self.close_reason) from self.transfer_data_exc
websockets.exceptions.ConnectionClosed: WebSocket connection is closed: code = 1006 (connection closed abnormally [internal]), no reason

The above exception was the direct cause of the following exception:

Traceback (most recent call last):
  File "C:\Users\yuya\AppData\Local\Programs\Python\Python37\lib\site-packages\discord\voice_client.py", line 242, in poll_voice_ws
    await self.ws.poll_event()
  File "C:\Users\yuya\AppData\Local\Programs\Python\Python37\lib\site-packages\discord\gateway.py", line 738, in poll_event
    raise ConnectionClosed(exc, shard_id=None) from exc
discord.errors.ConnectionClosed: WebSocket connection is closed: code = 1006 (connection closed abnormally [internal]), no reason
2020-01-09 21:38:33,461:ERROR:discord.voice_client: Disconnected from voice... Reconnecting in 0.06s.
Traceback (most recent call last):
  File "C:\Users\yuya\AppData\Local\Programs\Python\Python37\lib\site-packages\discord\gateway.py", line 735, in poll_event
    msg = await asyncio.wait_for(self.recv(), timeout=30.0, loop=self.loop)
  File "C:\Users\yuya\AppData\Local\Programs\Python\Python37\lib\asyncio\tasks.py", line 442, in wait_for
    return fut.result()
  File "C:\Users\yuya\AppData\Local\Programs\Python\Python37\lib\site-packages\websockets\protocol.py", line 350, in recv
    yield from self.ensure_open()
  File "C:\Users\yuya\AppData\Local\Programs\Python\Python37\lib\site-packages\websockets\protocol.py", line 512, in ensure_open
    self.close_code, self.close_reason) from self.transfer_data_exc
websockets.exceptions.ConnectionClosed: WebSocket connection is closed: code = 1001 (going away), no reason

The above exception was the direct cause of the following exception:

Traceback (most recent call last):
  File "C:\Users\yuya\AppData\Local\Programs\Python\Python37\lib\site-packages\discord\voice_client.py", line 242, in poll_voice_ws
    await self.ws.poll_event()
  File "C:\Users\yuya\AppData\Local\Programs\Python\Python37\lib\site-packages\discord\gateway.py", line 738, in poll_event
    raise ConnectionClosed(exc, shard_id=None) from exc
discord.errors.ConnectionClosed: WebSocket connection is closed: code = 1001 (going away), no reason
2020-01-10 06:27:34,174:WARNING:discord.gateway: Shard ID None has stopped responding to the gateway. Closing and restarting.
2020-01-10 15:38:58,010:WARNING:discord.gateway: Unknown event PRESENCES_REPLACE.
2020-01-10 16:04:34,547:WARNING:discord.gateway: Unknown event PRESENCES_REPLACE.
2020-01-10 16:20:03,442:WARNING:discord.gateway: Unknown event PRESENCES_REPLACE.
2020-01-13 22:17:46,628:ERROR:discord.voice_client: Disconnected from voice... Reconnecting in 0.81s.
Traceback (most recent call last):
  File "C:\Users\yuya\AppData\Local\Programs\Python\Python37\lib\site-packages\websockets\protocol.py", line 528, in transfer_data
    msg = yield from self.read_message()
  File "C:\Users\yuya\AppData\Local\Programs\Python\Python37\lib\site-packages\websockets\protocol.py", line 580, in read_message
    frame = yield from self.read_data_frame(max_size=self.max_size)
  File "C:\Users\yuya\AppData\Local\Programs\Python\Python37\lib\site-packages\websockets\protocol.py", line 645, in read_data_frame
    frame = yield from self.read_frame(max_size)
  File "C:\Users\yuya\AppData\Local\Programs\Python\Python37\lib\site-packages\websockets\protocol.py", line 710, in read_frame
    extensions=self.extensions,
  File "C:\Users\yuya\AppData\Local\Programs\Python\Python37\lib\site-packages\websockets\framing.py", line 100, in read
    data = yield from reader(2)
  File "C:\Users\yuya\AppData\Local\Programs\Python\Python37\lib\asyncio\streams.py", line 677, in readexactly
    raise IncompleteReadError(incomplete, n)
asyncio.streams.IncompleteReadError: 0 bytes read on a total of 2 expected bytes

The above exception was the direct cause of the following exception:

Traceback (most recent call last):
  File "C:\Users\yuya\AppData\Local\Programs\Python\Python37\lib\site-packages\discord\gateway.py", line 735, in poll_event
    msg = await asyncio.wait_for(self.recv(), timeout=30.0, loop=self.loop)
  File "C:\Users\yuya\AppData\Local\Programs\Python\Python37\lib\asyncio\tasks.py", line 442, in wait_for
    return fut.result()
  File "C:\Users\yuya\AppData\Local\Programs\Python\Python37\lib\site-packages\websockets\protocol.py", line 350, in recv
    yield from self.ensure_open()
  File "C:\Users\yuya\AppData\Local\Programs\Python\Python37\lib\site-packages\websockets\protocol.py", line 501, in ensure_open
    self.close_code, self.close_reason) from self.transfer_data_exc
websockets.exceptions.ConnectionClosed: WebSocket connection is closed: code = 1006 (connection closed abnormally [internal]), no reason

The above exception was the direct cause of the following exception:

Traceback (most recent call last):
  File "C:\Users\yuya\AppData\Local\Programs\Python\Python37\lib\site-packages\discord\voice_client.py", line 242, in poll_voice_ws
    await self.ws.poll_event()
  File "C:\Users\yuya\AppData\Local\Programs\Python\Python37\lib\site-packages\discord\gateway.py", line 738, in poll_event
    raise ConnectionClosed(exc, shard_id=None) from exc
discord.errors.ConnectionClosed: WebSocket connection is closed: code = 1006 (connection closed abnormally [internal]), no reason
2020-01-14 00:04:35,767:ERROR:discord.voice_client: Disconnected from voice... Reconnecting in 0.99s.
Traceback (most recent call last):
  File "C:\Users\yuya\AppData\Local\Programs\Python\Python37\lib\site-packages\discord\gateway.py", line 735, in poll_event
    msg = await asyncio.wait_for(self.recv(), timeout=30.0, loop=self.loop)
  File "C:\Users\yuya\AppData\Local\Programs\Python\Python37\lib\asyncio\tasks.py", line 442, in wait_for
    return fut.result()
  File "C:\Users\yuya\AppData\Local\Programs\Python\Python37\lib\site-packages\websockets\protocol.py", line 350, in recv
    yield from self.ensure_open()
  File "C:\Users\yuya\AppData\Local\Programs\Python\Python37\lib\site-packages\websockets\protocol.py", line 512, in ensure_open
    self.close_code, self.close_reason) from self.transfer_data_exc
websockets.exceptions.ConnectionClosed: WebSocket connection is closed: code = 1001 (going away), no reason

The above exception was the direct cause of the following exception:

Traceback (most recent call last):
  File "C:\Users\yuya\AppData\Local\Programs\Python\Python37\lib\site-packages\discord\voice_client.py", line 242, in poll_voice_ws
    await self.ws.poll_event()
  File "C:\Users\yuya\AppData\Local\Programs\Python\Python37\lib\site-packages\discord\gateway.py", line 738, in poll_event
    raise ConnectionClosed(exc, shard_id=None) from exc
discord.errors.ConnectionClosed: WebSocket connection is closed: code = 1001 (going away), no reason
2020-01-14 00:32:04,540:WARNING:discord.gateway: Shard ID None has stopped responding to the gateway. Closing and restarting.
